Workbook

Sheet Sheet1
C1: total | D1: industry | E1: household | F1: power | G1: industry-power | H1: industry-household | I1: calcuations | J1: note
A2: AT | B2: =VLOOKUP(A2,Sheet2!$A$2:$A$29,1,FALSE) -> AT | C2: aggm | F2: energy-charts | H2: calculated | I2: industry-household
A3: BE | B3: =VLOOKUP(A3,Sheet2!$A$2:$A$29,1,FALSE) -> BE | C3: calculated | D3: entsog | E3: entsog | F3: entsog | I3: sum for total
A4: BG | B4: =VLOOKUP(A4,Sheet2!$A$2:$A$29,1,FALSE) -> BG | C4: entsog | F4: energy-charts | H4: calculated | I4: industry-household
A5: HR | B5: =VLOOKUP(A5,Sheet2!$A$2:$A$29,1,FALSE) -> HR | C5: entsog | F5: energy-charts | H5: calculated | I5: industry-household
A6: CZ | B6: =VLOOKUP(A6,Sheet2!$A$2:$A$29,1,FALSE) -> CZ | C6: eurostat | F6: energy-charts | H6: calculated | I6: industry-household
A7: DK | B7: =VLOOKUP(A7,Sheet2!$A$2:$A$29,1,FALSE) -> DK | C7: energinet | F7: energy-charts | H7: calculated | I7: industry-household
A8: EE | B8: =VLOOKUP(A8,Sheet2!$A$2:$A$29,1,FALSE) -> EE | C8: entsog | F8: energy-charts | H8: calculated | I8: industry-household
A9: ES | B9: =VLOOKUP(A9,Sheet2!$A$2:$A$29,1,FALSE) -> ES | C9: enagas | F9: enagas | H9: calculated | I9: industry-household
A10: FI | B10: =VLOOKUP(A10,Sheet2!$A$2:$A$29,1,FALSE) -> FI | C10: eurostat | F10: energy-charts | H10: calculated | I10: industry-household
A11: FR | B11: =VLOOKUP(A11,Sheet2!$A$2:$A$29,1,FALSE) -> FR | C11: calculated | D11: grtgaz; entsog | E11: grtgaz; entsog | F11: grtgaz | I11: sum grtgaz and entsog, sum for total
A12: DE | B12: =VLOOKUP(A12,Sheet2!$A$2:$A$29,1,FALSE) -> DE | C12: trading hub europe | F12: energy-charts | J12: for monthly data we use BNetzA for household and can hence calculate industry demand
A13: GR | B13: =VLOOKUP(A13,Sheet2!$A$2:$A$29,1,FALSE) -> GR | C13: eurostat | F13: energy-charts | H13: calculated | I13: industry-household
A14: HU | B14: =VLOOKUP(A14,Sheet2!$A$2:$A$29,1,FALSE) -> HU | C14: calculated | D14: calculated | E14: entsog | F14: energy-charts | G14: entsog | I14: subtract for industry; sum for total
A15: IE | B15: =VLOOKUP(A15,Sheet2!$A$2:$A$29,1,FALSE) -> IE | C15: gas-networks-ireland | D15: gas-networks-ireland | E15: gas-networks-ireland | F15: gas-networks-ireland | I15: none
A16: IT | B16: =VLOOKUP(A16,Sheet2!$A$2:$A$29,1,FALSE) -> IT | C16: calculated | D16: entsog | E16: entsog | F16: entsog | I16: sum for total
A17: LV | B17: =VLOOKUP(A17,Sheet2!$A$2:$A$29,1,FALSE) -> LV | C17: entsog | F17: energy-charts | H17: calculated | I17: industry-household
A18: LT | B18: =VLOOKUP(A18,Sheet2!$A$2:$A$29,1,FALSE) -> LT | C18: eurostat | F18: energy-charts | H18: calculated | I18: industry-household
A19: LU | B19: =VLOOKUP(A19,Sheet2!$A$2:$A$29,1,FALSE) -> LU | C19: calculated | D19: calculated | E19: entsog | F19: energy-charts | G19: entsog | I19: subtract for industry; sum for total
A20: NL | B20: =VLOOKUP(A20,Sheet2!$A$2:$A$29,1,FALSE) -> NL | C20: calculated | D20: entsog | E20: entsog | F20: entsog | I20: sum for total | L20: *check if CBS needed
A21: PL | B21: =VLOOKUP(A21,Sheet2!$A$2:$A$29,1,FALSE) -> PL | C21: entsog | F21: energy-charts | H21: calculated | I21: industry-household
A22: PT | B22: =VLOOKUP(A22,Sheet2!$A$2:$A$29,1,FALSE) -> PT | C22: calculated | D22: calculated | E22: entsog | F22: energy-charts | G22: entsog | I22: subtract for industry; sum for total
A23: RO | B23: =VLOOKUP(A23,Sheet2!$A$2:$A$29,1,FALSE) -> RO | C23: calculated | D23: calculated | E23: entsog | F23: energy-charts | G23: entsog | I23: subtract for industry; sum for total
A24: SK | B24: =VLOOKUP(A24,Sheet2!$A$2:$A$29,1,FALSE) -> SK | C24: eurostat | F24: energy-charts | H24: calculated | I24: industry-household
A25: SI | B25: =VLOOKUP(A25,Sheet2!$A$2:$A$29,1,FALSE) -> SI | C25: entsog | F25: energy-charts | H25: calculated | I25: industry-household
A26: SE | B26: =VLOOKUP(A26,Sheet2!$A$2:$A$29,1,FALSE) -> SE | C26: eurostat | F26: energy-charts | H26: calculated | I26: industry-household
A27: UK | B27: =VLOOKUP(A27,Sheet2!$A$2:$A$29,1,FALSE) -> #N/A | C27: national-grid | D27: national-grid | E27: national-grid | F27: national-grid | I27: none
A28: CY | B28: =VLOOKUP(A28,Sheet2!$A$2:$A$29,1,FALSE) -> CY
A29: MT | B29: =VLOOKUP(A29,Sheet2!$A$2:$A$29,1,FALSE) -> MT
C33: BE | D33: =VLOOKUP(C33,$A$2:$C$27,2,FALSE) -> BE
C34: CZ | D34: =VLOOKUP(C34,$A$2:$C$27,2,FALSE) -> CZ
C35: FI | D35: =VLOOKUP(C35,$A$2:$C$27,2,FALSE) -> FI
C36: GR | D36: =VLOOKUP(C36,$A$2:$C$27,2,FALSE) -> GR
C37: HU | D37: =VLOOKUP(C37,$A$2:$C$27,2,FALSE) -> HU
C38: IE | D38: =VLOOKUP(C38,$A$2:$C$27,2,FALSE) -> IE
C39: IT | D39: =VLOOKUP(C39,$A$2:$C$27,2,FALSE) -> IT
C40: LT | D40: =VLOOKUP(C40,$A$2:$C$27,2,FALSE) -> LT
C41: LU | D41: =VLOOKUP(C41,$A$2:$C$27,2,FALSE) -> LU
C42: NL | D42: =VLOOKUP(C42,$A$2:$C$27,2,FALSE) -> NL
C43: PT | D43: =VLOOKUP(C43,$A$2:$C$27,2,FALSE) -> PT
...

Sheet Sheet2
A1: country
A2: AT
A3: BE
A4: BG
A5: CY
A6: CZ
A7: DE
A8: DK
A9: EE
A10: ES
A11: EU27_2020
A12: FI
... A29: SK
